Workbook
Name \w: #REF!
Name \z: #REF!
Name _1990: #REF!
Name _PAS1990: #REF!
Name _PYG1990: #REF!
Name _PYG1999: [2]RESULTADOS!$O$1:$R$63
Name BALANCE: #REF!
Name ESF.ACTUAL: '2.ESF'!$E$75
Name ESF.PREVIO: '2.ESF'!$F$75
Name FLUJO.ACTUAL: '[1]5.FLUJO DE EFECTIVO'!$G$100
Name FLUJO.PREVIO: '[1]5.FLUJO DE EFECTIVO'!$H$100
Name PAT.ACTUAL: '[1]4.CAMBIOS EN EL PAT'!$M$29
Name PAT.PREVIO: '[1]4.CAMBIOS EN EL PAT'!$M$20
Name PYG: #REF!

Sheet 2.ESF
K2: jul
C3: ESTADOS FINANCIEROS INDIVIDUALES | J3: MES | K3: jul
C4: ESTADO DE SITUACIÓN FINANCIERA | J4: AÑO FINAL | K4: 2024
C5: Por el período terminados al 31 de julio de 2026 y 2025 | J5: AÑO INICIAL | K5: 2024
C7: =+'[1]1.CERTIFICACIÓN'!A6 -> OFTALMOLOGOS EL TESORO S.A.S
E9: 2026 | F9: 2025
D10: Notas | E10: Julio 2026 | F10: Julio 2025 | G10: $ Var | H10: % Var
C12: ACTIVO
C13: Activo corriente
A14: 11 | C14: Efectivo y equivalentes al efectivo | D14: 5 | E14: =+IFERROR((VLOOKUP((CONCATENATE($K$3,$E$9,$A14)),'[1]AÑO 2026'!$D:$I,6,0)),0) -> -4214553.1 | F14: =+IFERROR((VLOOKUP((CONCATENATE($K$3,$F$9,$A14)),'[1]AÑO 2025'!$D:$I,6,0)),0) -> 9.5596683e+08 | G14: =+E14-F14 -> -9.6018138e+08 | H14: =IFERROR(G14/F14,0) -> -1.0044087
A15: 12 | C15: Inversiones | E15: =+IFERROR((VLOOKUP((CONCATENATE($K$3,$E$9,$A15)),'[1]AÑO 2026'!$D:$I,6,0)),0) -> 0 | F15: =+IFERROR((VLOOKUP((CONCATENATE($K$3,$F$9,$A15)),'[1]AÑO 2025'!$D:$I,6,0)),0) -> 0 | G15: =+E15-F15 -> 0 | H15: =IFERROR(G15/F15,0) -> 0
A16: 13 | C16: Cuentas comerciales por cobrar y otras cuentas por cobrar | D16: 6 | E16: =+IFERROR((VLOOKUP((CONCATENATE($K$3,$E$9,$A16)),'[1]AÑO 2026'!$D:$I,6,0)),0) -> 2.7736917e+09 | F16: =+IFERROR((VLOOKUP((CONCATENATE($K$3,$F$9,$A16)),'[1]AÑO 2025'!$D:$I,6,0)),0) -> 1.3450386e+09 | G16: =+E16-F16 -> 1.4286531e+09 | H16: =IFERROR(G16/F16,0) -> 1.0621652
A17: 14 | C17: Inventarios | E17: =+IFERROR((VLOOKUP((CONCATENATE($K$3,$E$9,$A17)),'[1]AÑO 2026'!$D:$I,6,0)),0) -> 568990212 | F17: =+IFERROR((VLOOKUP((CONCATENATE($K$3,#REF!,$A17)),'[1]AÑO 2025'!$D:$I,6,0)),0) -> 0 | G17: =+E17-F17 -> 568990212 | H17: =IFERROR(G17/F17,0) -> 0
C18: Total activo corriente | E18: =+SUM(E14:E17) -> 3.3384673e+09 | F18: =+SUM(F14:F17) -> 2.3010054e+09 | G18: =SUM(G14:G17) -> 1.037462e+09 | H18: =IFERROR(G18/F18,0) -> 0.45087332
C19: Activos no corriente | H19: =IFERROR(G19/F19,0) -> 0
A20: 15 | C20: Propiedad, planta y equipo | D20: 7 | E20: =+IFERROR((VLOOKUP((CONCATENATE($K$3,$E$9,$A20)),'[1]AÑO 2026'!$D:$I,6,0)),0) -> 1.0046736e+10 | F20: =+IFERROR((VLOOKUP((CONCATENATE($K$3,$F$9,$A20)),'[1]AÑO 2025'!$D:$I,6,0)),0) -> 6.6617245e+09 | G20: =+E20-F20 -> 3.385011e+09 | H20: =IFERROR(G20/F20,0) -> 0.50812834
A21: 16 | C21: Activos intangibles | E21: =+IFERROR((VLOOKUP((CONCATENATE($K$3,$E$9,$A21)),'[1]AÑO 2026'!$D:$I,6,0)),0) -> 0 | F21: =+IFERROR((VLOOKUP((CONCATENATE($K$3,$F$9,$A21)),'[1]AÑO 2025'!$D:$I,6,0)),0) -> 0 | G21: =+E21-F21 -> 0 | H21: =IFERROR(G21/F21,0) -> 0
A22: 17 | C22: Activos diferidos | D22: 8 | E22: =+IFERROR((VLOOKUP((CONCATENATE($K$3,$E$9,$A22)),'[1]AÑO 2026'!$D:$I,6,0)),0) -> 2.7186446e+08 | F22: =+IFERROR((VLOOKUP((CONCATENATE($K$3,$F$9,$A22)),'[1]AÑO 2025'!$D:$I,6,0)),0) -> 118964993 | G22: =+E22-F22 -> 1.5289947e+08 | H22: =IFERROR(G22/F22,0) -> 1.2852476
A23: 18 | C23: Otros activos | E23: =+IFERROR((VLOOKUP((CONCATENATE($K$3,$E$9,$A23)),'[1]AÑO 2026'!$D:$I,6,0)),0) -> 0 | F23: =+IFERROR((VLOOKUP((CONCATENATE($K$3,$F$9,$A23)),'[1]AÑO 2025'!$D:$I,6,0)),0) -> 0 | G23: =+E23-F23 -> 0 | H23: =IFERROR(G23/F23,0) -> 0
A24: 19 | C24: Activo por impuesto diferido | E24: =+IFERROR((VLOOKUP((CONCATENATE($K$3,$E$9,$A24)),'[1]AÑO 2026'!$D:$I,6,0)),0) -> 0 | F24: =+IFERROR((VLOOKUP((CONCATENATE($K$3,$F$9,$A24)),'[1]AÑO 2025'!$D:$I,6,0)),0) -> 0 | G24: =+E24-F24 -> 0 | H24: =IFERROR(G24/F24,0) -> 0
C25: Total activo no corriente | E25: =+SUM(E20:E24) -> 1.03186e+10 | F25: =+SUM(F20:F24) -> 6.7806895e+09 | G25: =SUM(G20:G24) -> 3.5379105e+09 | H25: =IFERROR(G25/F25,0) -> 0.52176264
C26: TOTAL ACTIVOS | E26: =+E18+E25 -> 1.3657067e+10 | F26: =+F18+F25 -> 9.0816949e+09 | G26: =+E26-F26 -> 4.5753724e+09 | H26: =IFERROR(G26/F26,0) -> 0.5038016
C27: PASIVO
C28: Pasivo corriente | H28: =IFERROR(G28/F28,0) -> 0
A29: 2105 | C29: Obligaciones financieras | D29: 9 | E29: =+IFERROR((VLOOKUP((CONCATENATE($K$3,$E$9,$A29)),'[1]AÑO 2026'!$D:$I,6,0)),0) -> -5.6887498e+08 | F29: =+IFERROR((VLOOKUP((CONCATENATE($K$3,$F$9,$A29)),'[1]AÑO 2025'!$D:$I,6,0)),0) -> -6.2439718e+08 | G29: =+E29-F29 -> 55522206 | H29: =IFERROR(G29/F29,0) -> -0.088921294 | J29: ESTE VALOR ES MANUAL
A30: 22050501 | C30: Cuentas por pagar a proveedores | D30: 10 | E30: =+IFERROR((VLOOKUP((CONCATENATE($K$3,$E$9,$A30)),'[1]AÑO 2026'!$D:$I,6,0)),0) -> -3.0635048e+09 | F30: =+IFERROR((VLOOKUP((CONCATENATE($K$3,$F$9,$A30)),'[1]AÑO 2025'!$D:$I,6,0)),0) -> -1.5435094e+09 | G30: =+E30-F30 -> -1.5199954e+09 | H30: =IFERROR(G30/F30,0) -> 0.98476594
A31: 23 | C31: Cuentas comerciales por pagar y otras cuentas por pagar | D31: 11 | E31: =+IFERROR((VLOOKUP((CONCATENATE($K$3,$E$9,$A31)),'[1]AÑO 2026'!$D:$I,6,0)),0) -> -3.9087047e+08 | F31: =+IFERROR((VLOOKUP((CONCATENATE($K$3,$F$9,$A31)),'[1]AÑO 2025'!$D:$I,6,0)),0) -> -2.5971036e+08 | G31: =+E31-F31 -> -1.3116011e+08 | H31: =IFERROR(G31/F31,0) -> 0.50502456
A32: 24 | C32: Impuestos, gravámenes y tasas | E32: =+IFERROR((VLOOKUP((CONCATENATE($K$3,$E$9,$A32)),'[1]AÑO 2026'!$D:$I,6,0)),0) -> -394074690 | F32: =+IFERROR((VLOOKUP((CONCATENATE($K$3,$F$9,$A32)),'[1]AÑO 2025'!$D:$I,6,0)),0) -> 0 | G32: =+E32-F32 -> -394074690 | H32: =IFERROR(G32/F32,0) -> 0
A33: 25 | C33: Pasivo por beneficios a empleados | D33: 12 | E33: =+IFERROR((VLOOKUP((CONCATENATE($K$3,$E$9,$A33)),'[1]AÑO 2026'!$D:$I,6,0)),0) -> -2.7187872e+08 | F33: =+IFERROR((VLOOKUP((CONCATENATE($K$3,$F$9,$A33)),'[1]AÑO 2025'!$D:$I,6,0)),0) -> -1.0749475e+08 | G33: =+E33-F33 -> -1.6438397e+08 | H33: =IFERROR(G33/F33,0) -> 1.5292278
A34: 26 | C34: Pasivos estimados y provisiones | E34: =+IFERROR((VLOOKUP((CONCATENATE($K$3,$E$9,$A34)),'[1]AÑO 2026'!$D:$I,6,0)),0) -> 0 | F34: =+IFERROR((VLOOKUP((CONCATENATE($K$3,$F$9,$A34)),'[1]AÑO 2025'!$D:$I,6,0)),0) -> 0 | G34: =+E34-F34 -> 0 | H34: =IFERROR(G34/F34,0) -> 0
A35: 28 | C35: Anticipos recibidos | D35: 13 | E35: =+IFERROR((VLOOKUP((CONCATENATE($K$3,$E$9,$A35)),'[1]AÑO 2026'!$D:$I,6,0)),0) -> -6.8779381e+08 | F35: =+IFERROR((VLOOKUP((CONCATENATE($K$3,$F$9,$A35)),'[1]AÑO 2025'!$D:$I,6,0)),0) -> -2.7143938e+09 | G35: =+E35-F35 -> 2.0266e+09 | H35: =IFERROR(G35/F35,0) -> -0.74661237
C36: Total pasivo corriente | E36: =+SUM(E29:E35) -> -5.3769975e+09 | F36: =+SUM(F29:F35) -> -5.2495055e+09 | G36: =+E36-F36 -> -1.2749199e+08 | H36: =IFERROR(G36/F36,0) -> 0.024286476
C37: Pasivo no corriente | H37: =IFERROR(G37/F37,0) -> 0
A38: 2115 | C38: Obligaciones financieras | D38: 9 | E38: =+IFERROR((VLOOKUP((CONCATENATE($K$3,$E$9,$A38)),'[1]AÑO 2026'!$D:$I,6,0)),0) -> -1.6251785e+08 | F38: =+IFERROR((VLOOKUP((CONCATENATE($K$3,$F$9,$A38)),'[1]AÑO 2025'!$D:$I,6,0)),0) -> -56922180 | G38: =+E38-F38 -> -1.0559567e+08 | H38: =IFERROR(G38/F38,0) -> 1.8550883
A39: 22050502 | C39: Cuentas por pagar a proveedores | D39: 10 | E39: =+IFERROR((VLOOKUP((CONCATENATE($K$3,$E$9,$A39)),'[1]AÑO 2026'!$D:$I,6,0)),0) -> -1710110688 | F39: =+IFERROR((VLOOKUP((CONCATENATE($K$3,$F$9,$A39)),'[1]AÑO 2025'!$D:$I,6,0)),0) -> -1051598275 | G39: =+E39-F39 -> -658512413 | H39: =IFERROR(G39/F39,0) -> 0.6262015
A40: 23 | C40: Cuentas comerciales por pagar y otras cuentas por pagar
A41: 29 | C41: Pasivo por impuesto diferido | D41: 14 | E41: =+IFERROR((VLOOKUP((CONCATENATE($K$3,$E$9,$A41)),'[1]AÑO 2026'!$D:$I,6,0)),0) -> -80203562 | F41: =+IFERROR((VLOOKUP((CONCATENATE($K$3,$F$9,$A41)),'[1]AÑO 2025'!$D:$I,6,0)),0) -> -80203562 | G41: =+E41-F41 -> 0 | H41: =IFERROR(G41/F41,0) -> 0
C42: Total pasivo no corriente | E42: =SUM(E38:E41) -> -1.9528321e+09 | F42: =SUM(F38:F41) -> -1.188724e+09 | G42: =+E42-F42 -> -7.6410808e+08 | H42: =IFERROR(G42/F42,0) -> 0.64279687
C43: TOTAL PASIVOS | E43: =+E36+E42 -> -7.3298296e+09 | F43: =+F36+F42 -> -6.4382295e+09 | G43: =+E43-F43 -> -8.9160007e+08 | H43: =IFERROR(G43/F43,0) -> 0.13848529
C44: PATRIMONIO
...

Sheet 3.ERI
K2: jul
C3: =+'2.ESF'!C3 -> ESTADOS FINANCIEROS INDIVIDUALES | J3: MES | K3: feb
C4: ESTADO DE RESULTADOS INTEGRAL | K4: 2024
C5: Por el período terminados al 31 de julio de 2026 y 2025
C7: =+'2.ESF'!C7 -> OFTALMOLOGOS EL TESORO S.A.S
E9: 2026 | F9: 2025
D10: Notas | E10: Julio 2026 | F10: Julio 2025 | G10: $ Var | H10: % Var
C12: INGRESOS OPERACIONALES
A13: 41 | C13: =PROPER(+IFERROR(VLOOKUP(A13,'[1]AÑO 2025'!C:I,3,FALSE),0)) -> Ingresos Ordinarios | D13: 16 | E13: =+IFERROR((VLOOKUP((CONCATENATE($K$2,$E$9,$A13)),'[1]AÑO 2026'!$D:$I,6,0)),0)*-1 -> 10629413901 | F13: =+IFERROR((VLOOKUP((CONCATENATE($K$2,$F$9,$A13)),'[1]AÑO 2025'!$D:$I,6,0)),0)*-1 -> 7.8475806e+09 | G13: =+E13-F13 -> 2.7818333e+09 | H13: =IFERROR(G13/F13,0) -> 0.35448292
A14: 6 | C14: =PROPER(+IFERROR(VLOOKUP(A14,'[1]AÑO 2025'!C:I,3,FALSE),0)) -> Costo De Ventas Y Prestación De Servicios | E14: =+IFERROR((VLOOKUP((CONCATENATE($K$2,$E$9,$A14)),'[1]AÑO 2026'!$D:$I,6,0)),0)*-1 -> -6.0044849e+09 | F14: =+IFERROR((VLOOKUP((CONCATENATE($K$2,$F$9,$A14)),'[1]AÑO 2025'!$D:$I,6,0)),0)*-1 -> -4.3795629e+09 | G14: =+E14-F14 -> -1.6249219e+09 | H14: =IFERROR(G14/F14,0) -> 0.37102376
A15: 7 | C15: =PROPER(+IFERROR(VLOOKUP(A15,'[1]AÑO 2025'!C:I,3,FALSE),0)) -> Costos De Producción | E15: =+IFERROR((VLOOKUP((CONCATENATE($K$2,$E$9,$A15)),'[1]AÑO 2026'!$D:$I,6,0)),0)*-1 -> -660802687 | F15: =+IFERROR((VLOOKUP((CONCATENATE($K$2,$F$9,$A15)),'[1]AÑO 2025'!$D:$I,6,0)),0)*-1 -> -2.3449977e+08 | G15: =+E15-F15 -> -4.2630291e+08 | H15: =IFERROR(G15/F15,0) -> 1.8179246
C16: Utilidad Bruta | E16: =+SUM(E13:E15) -> 3.9641263e+09 | F16: =+SUM(F13:F15) -> 3.2335179e+09 | G16: =+E16-F16 -> 7.3060847e+08 | H16: =IFERROR(G16/F16,0) -> 0.22594849
E17: =+E16/E13 -> 0.37293932 | F17: =+F16/F13 -> 0.4120401 | G17: =+E17-F17 -> -0.039100782 | H17: =+F17-G17 -> 0.45114088
C18: GASTROS ADMINISTRATIVOS
A19: 5105 | C19: =PROPER(+IFERROR(VLOOKUP(A19,'[1]AÑO 2025'!C:I,3,FALSE),0)) -> Gasto De Personal | D19: 17 | E19: =+IFERROR((VLOOKUP((CONCATENATE($K$2,$E$9,$A19)),'[1]AÑO 2026'!$D:$I,6,0)),0)*-1 -> -1.0444162e+09 | F19: =+IFERROR((VLOOKUP((CONCATENATE($K$2,$F$9,$A19)),'[1]AÑO 2025'!$D:$I,6,0)),0)*-1 -> -7.5852333e+08 | G19: =+E19-F19 -> -2.8589285e+08 | H19: =IFERROR(G19/F19,0) -> 0.37690713
A20: 5110 | C20: =PROPER(+IFERROR(VLOOKUP(A20,'[1]AÑO 2025'!C:I,3,FALSE),0)) -> Gastos Honorarios Administración | D20: 17 | E20: =+IFERROR((VLOOKUP((CONCATENATE($K$2,$E$9,$A20)),'[1]AÑO 2026'!$D:$I,6,0)),0)*-1 -> -1.9991019e+08 | F20: =+IFERROR((VLOOKUP((CONCATENATE($K$2,$F$9,$A20)),'[1]AÑO 2025'!$D:$I,6,0)),0)*-1 -> -1.4692011e+08 | G20: =+E20-F20 -> -52990074 | H20: =IFERROR(G20/F20,0) -> 0.36067269
A21: 5115 | C21: =PROPER(+IFERROR(VLOOKUP(A21,'[1]AÑO 2025'!C:I,3,FALSE),0)) -> Gastos Impuestos Administración | D21: 17 | E21: =+IFERROR((VLOOKUP((CONCATENATE($K$2,$E$9,$A21)),'[1]AÑO 2026'!$D:$I,6,0)),0)*-1 -> -49539473 | F21: =+IFERROR((VLOOKUP((CONCATENATE($K$2,$F$9,$A21)),'[1]AÑO 2025'!$D:$I,6,0)),0)*-1 -> -45445510 | G21: =+E21-F21 -> -4093963.4 | H21: =IFERROR(G21/F21,0) -> 0.090085102
A22: 5120 | C22: =PROPER(+IFERROR(VLOOKUP(A22,'[1]AÑO 2025'!C:I,3,FALSE),0)) -> Gastos Arrendamientos Administración | D22: 17 | E22: =+IFERROR((VLOOKUP((CONCATENATE($K$2,$E$9,$A22)),'[1]AÑO 2026'!$D:$I,6,0)),0)*-1 -> -7.416161e+08 | F22: =+IFERROR((VLOOKUP((CONCATENATE($K$2,$F$9,$A22)),'[1]AÑO 2025'!$D:$I,6,0)),0)*-1 -> -5.0376043e+08 | G22: =+E22-F22 -> -2.3785567e+08 | H22: =IFERROR(G22/F22,0) -> 0.47216028
A23: 5125 | C23: =PROPER(+IFERROR(VLOOKUP(A23,'[1]AÑO 2025'!C:I,3,FALSE),0)) -> Gastos Contribuciones Y Afiliaciones Administración | D23: 17 | E23: =+IFERROR((VLOOKUP((CONCATENATE($K$2,$E$9,$A23)),'[1]AÑO 2026'!$D:$I,6,0)),0)*-1 -> -1.2001923e+08 | F23: =+IFERROR((VLOOKUP((CONCATENATE($K$2,$F$9,$A23)),'[1]AÑO 2025'!$D:$I,6,0)),0)*-1 -> -91984229 | G23: =+E23-F23 -> -28034999 | H23: =IFERROR(G23/F23,0) -> 0.3047805
A24: 5130 | C24: =PROPER(+IFERROR(VLOOKUP(A24,'[1]AÑO 2025'!C:I,3,FALSE),0)) -> Gastos Seguros Administración | D24: 17 | E24: =+IFERROR((VLOOKUP((CONCATENATE($K$2,$E$9,$A24)),'[1]AÑO 2026'!$D:$I,6,0)),0)*-1 -> -1.3950366e+08 | F24: =+IFERROR((VLOOKUP((CONCATENATE($K$2,$F$9,$A24)),'[1]AÑO 2025'!$D:$I,6,0)),0)*-1 -> -91009550 | G24: =+E24-F24 -> -48494113 | H24: =IFERROR(G24/F24,0) -> 0.53284642
A25: 5135 | C25: =PROPER(+IFERROR(VLOOKUP(A25,'[1]AÑO 2025'!C:I,3,FALSE),0)) -> Gastos Servicios Administración | D25: 17 | E25: =+IFERROR((VLOOKUP((CONCATENATE($K$2,$E$9,$A25)),'[1]AÑO 2026'!$D:$I,6,0)),0)*-1 -> -3.5713966e+08 | F25: =+IFERROR((VLOOKUP((CONCATENATE($K$2,$F$9,$A25)),'[1]AÑO 2025'!$D:$I,6,0)),0)*-1 -> -2.5448915e+08 | G25: =+E25-F25 -> -1.026505e+08 | H25: =IFERROR(G25/F25,0) -> 0.40335905
A26: 5140 | C26: =PROPER(+IFERROR(VLOOKUP(A26,'[1]AÑO 2025'!C:I,3,FALSE),0)) -> Gastos Legales Administración | D26: 17 | E26: =+IFERROR((VLOOKUP((CONCATENATE($K$2,$E$9,$A26)),'[1]AÑO 2026'!$D:$I,6,0)),0)*-1 -> -9086208.2 | F26: =+IFERROR((VLOOKUP((CONCATENATE($K$2,$F$9,$A26)),'[1]AÑO 2025'!$D:$I,6,0)),0)*-1 -> -5839200.3 | G26: =+E26-F26 -> -3247007.9 | H26: =IFERROR(G26/F26,0) -> 0.55607065
A27: 5145 | C27: =PROPER(+IFERROR(VLOOKUP(A27,'[1]AÑO 2025'!C:I,3,FALSE),0)) -> Gastos Mantenimiento Administración | D27: 17 | E27: =+IFERROR((VLOOKUP((CONCATENATE($K$2,$E$9,$A27)),'[1]AÑO 2026'!$D:$I,6,0)),0)*-1 -> -3.0602756e+08 | F27: =+IFERROR((VLOOKUP((CONCATENATE($K$2,$F$9,$A27)),'[1]AÑO 2025'!$D:$I,6,0)),0)*-1 -> -1.7079617e+08 | G27: =+E27-F27 -> -1.3523139e+08 | H27: =IFERROR(G27/F27,0) -> 0.79177066
A28: 5150 | C28: =PROPER(+IFERROR(VLOOKUP(A28,'[1]AÑO 2025'!C:I,3,FALSE),0)) -> 0 | D28: 17 | E28: =+IFERROR((VLOOKUP((CONCATENATE($K$2,$E$9,$A28)),'[1]AÑO 2026'!$D:$I,6,0)),0)*-1 -> 0 | F28: =+IFERROR((VLOOKUP((CONCATENATE($K$2,$F$9,$A28)),'[1]AÑO 2025'!$D:$I,6,0)),0)*-1 -> 0 | G28: =+E28-F28 -> 0 | H28: =IFERROR(G28/F28,0) -> 0
A29: 5155 | C29: =PROPER(+IFERROR(VLOOKUP(A29,'[1]AÑO 2026'!C:I,3,FALSE),0)) -> Gastos De Viaje Administración | D29: 17 | E29: =+IFERROR((VLOOKUP((CONCATENATE($K$2,$E$9,$A29)),'[1]AÑO 2026'!$D:$I,6,0)),0)*-1 -> -828817.01 | F29: =+IFERROR((VLOOKUP((CONCATENATE($K$2,$F$9,$A29)),'[1]AÑO 2025'!$D:$I,6,0)),0)*-1 -> -810813 | G29: =+E29-F29 -> -18004.01 | H29: =IFERROR(G29/F29,0) -> 0.022204886
A30: 5160 | C30: =PROPER(+IFERROR(VLOOKUP(A30,'[1]AÑO 2025'!C:I,3,FALSE),0)) -> Gastos Depreciaciones Administración | D30: 17 | E30: =+IFERROR((VLOOKUP((CONCATENATE($K$2,$E$9,$A30)),'[1]AÑO 2026'!$D:$I,6,0)),0)*-1 -> -441338797 | F30: =+IFERROR((VLOOKUP((CONCATENATE($K$2,$F$9,$A30)),'[1]AÑO 2025'!$D:$I,6,0)),0)*-1 -> -249105084 | G30: =+E30-F30 -> -192233713 | H30: =IFERROR(G30/F30,0) -> 0.77169727
A31: 5165 | C31: =PROPER(+IFERROR(VLOOKUP(A31,'[1]AÑO 2025'!C:I,3,FALSE),0)) -> Amortizaciones | D31: 17 | E31: =+IFERROR((VLOOKUP((CONCATENATE($K$2,$E$9,$A31)),'[1]AÑO 2026'!$D:$I,6,0)),0)*-1 -> -66099803 | F31: =+IFERROR((VLOOKUP((CONCATENATE($K$2,$F$9,$A31)),'[1]AÑO 2025'!$D:$I,6,0)),0)*-1 -> -35191528 | G31: =+E31-F31 -> -30908275 | H31: =IFERROR(G31/F31,0) -> 0.87828739
A32: 5195 | C32: =PROPER(+IFERROR(VLOOKUP(A32,'[1]AÑO 2025'!C:I,3,FALSE),0)) -> Gastos Diversos Administración | D32: 17 | E32: =+IFERROR((VLOOKUP((CONCATENATE($K$2,$E$9,$A32)),'[1]AÑO 2026'!$D:$I,6,0)),0)*-1-100000 -> -2.0413889e+08 | F32: =+IFERROR((VLOOKUP((CONCATENATE($K$2,$F$9,$A32)),'[1]AÑO 2025'!$D:$I,6,0)),0)*-1 -> -52779625 | G32: =+E32-F32 -> -1.5135927e+08 | H32: =IFERROR(G32/F32,0) -> 2.8677594
A33: 5199 | C33: Gastos en cuentas de participación | D33: 17 | E33: =+IFERROR((VLOOKUP((CONCATENATE($K$3,$E$9,$A33)),'[1]AÑO 2026'!$D:$I,6,0)),0)*-1 -> 0 | F33: =+IFERROR((VLOOKUP((CONCATENATE($K$3,$F$9,$A33)),'[1]AÑO 2025'!$D:$I,6,0)),0) -> 0 | G33: =+E33-F33 -> 0 | H33: =IFERROR(G33/F33,0) -> 0
C34: Total gastos administrativos | E34: =+SUM(E19:E33) -> -3.6796646e+09 | F34: =+SUM(F19:F32)-F33 -> -2.4066547e+09 | G34: =+E34-F34 -> -1.2730098e+09 | H34: =IFERROR(G34/F34,0) -> 0.52895408
C35: GASTOS DE VENTAS
A36: 5205 | C36: =PROPER(+IFERROR(VLOOKUP(A36,'[1]AÑO 2025'!C:I,3,FALSE),0)) -> 0 | E36: =+IFERROR((VLOOKUP((CONCATENATE($K$3,$E$9,$A36)),'[1]AÑO 2026'!$D:$I,6,0)),0)*-1 -> 0 | F36: =+IFERROR((VLOOKUP((CONCATENATE($K$3,$F$9,$A36)),'[1]AÑO 2025'!$D:$I,6,0)),0)*-1 -> 0 | G36: =+E36-F36 -> 0 | H36: =IFERROR(G36/F36,0) -> 0
A37: 5210 | C37: =PROPER(+IFERROR(VLOOKUP(A37,'[1]AÑO 2025'!C:I,3,FALSE),0)) -> 0 | E37: =+IFERROR((VLOOKUP((CONCATENATE($K$3,$E$9,$A37)),'[1]AÑO 2026'!$D:$I,6,0)),0)*-1 -> 0 | F37: =+IFERROR((VLOOKUP((CONCATENATE($K$3,$F$9,$A37)),'[1]AÑO 2025'!$D:$I,6,0)),0)*-1 -> 0 | G37: =+E37-F37 -> 0 | H37: =IFERROR(G37/F37,0) -> 0
A38: 5215 | C38: =PROPER(+IFERROR(VLOOKUP(A38,'[1]AÑO 2025'!C:I,3,FALSE),0)) -> 0 | E38: =+IFERROR((VLOOKUP((CONCATENATE($K$3,$E$9,$A38)),'[1]AÑO 2026'!$D:$I,6,0)),0)*-1 -> 0 | F38: =+IFERROR((VLOOKUP((CONCATENATE($K$3,$F$9,$A38)),'[1]AÑO 2025'!$D:$I,6,0)),0)*-1 -> 0 | G38: =+E38-F38 -> 0 | H38: =IFERROR(G38/F38,0) -> 0
A39: 5220 | C39: =PROPER(+IFERROR(VLOOKUP(A39,'[1]AÑO 2025'!C:I,3,FALSE),0)) -> 0 | E39: =+IFERROR((VLOOKUP((CONCATENATE($K$3,$E$9,$A39)),'[1]AÑO 2026'!$D:$I,6,0)),0)*-1 -> 0 | F39: =+IFERROR((VLOOKUP((CONCATENATE($K$3,$F$9,$A39)),'[1]AÑO 2025'!$D:$I,6,0)),0)*-1 -> 0 | G39: =+E39-F39 -> 0 | H39: =IFERROR(G39/F39,0) -> 0
A40: 5225 | C40: =PROPER(+IFERROR(VLOOKUP(A40,'[1]AÑO 2025'!C:I,3,FALSE),0)) -> 0 | E40: =+IFERROR((VLOOKUP((CONCATENATE($K$3,$E$9,$A40)),'[1]AÑO 2026'!$D:$I,6,0)),0)*-1 -> 0 | F40: =+IFERROR((VLOOKUP((CONCATENATE($K$3,$F$9,$A40)),'[1]AÑO 2025'!$D:$I,6,0)),0)*-1 -> 0 | G40: =+E40-F40 -> 0 | H40: =IFERROR(G40/F40,0) -> 0
A41: 5230 | C41: =PROPER(+IFERROR(VLOOKUP(A41,'[1]AÑO 2025'!C:I,3,FALSE),0)) -> 0 | E41: =+IFERROR((VLOOKUP((CONCATENATE($K$3,$E$9,$A41)),'[1]AÑO 2026'!$D:$I,6,0)),0)*-1 -> 0 | F41: =+IFERROR((VLOOKUP((CONCATENATE($K$3,$F$9,$A41)),'[1]AÑO 2025'!$D:$I,6,0)),0)*-1 -> 0 | G41: =+E41-F41 -> 0 | H41: =IFERROR(G41/F41,0) -> 0
A42: 5235 | C42: =PROPER(+IFERROR(VLOOKUP(A42,'[1]AÑO 2025'!C:I,3,FALSE),0)) -> 0 | E42: =+IFERROR((VLOOKUP((CONCATENATE($K$3,$E$9,$A42)),'[1]AÑO 2026'!$D:$I,6,0)),0)*-1 -> 0 | F42: =+IFERROR((VLOOKUP((CONCATENATE($K$3,$F$9,$A42)),'[1]AÑO 2025'!$D:$I,6,0)),0)*-1 -> 0 | G42: =+E42-F42 -> 0 | H42: =IFERROR(G42/F42,0) -> 0
A43: 5240 | C43: =PROPER(+IFERROR(VLOOKUP(A43,'[1]AÑO 2025'!C:I,3,FALSE),0)) -> 0 | E43: =+IFERROR((VLOOKUP((CONCATENATE($K$3,$E$9,$A43)),'[1]AÑO 2026'!$D:$I,6,0)),0)*-1 -> 0 | F43: =+IFERROR((VLOOKUP((CONCATENATE($K$3,$F$9,$A43)),'[1]AÑO 2025'!$D:$I,6,0)),0)*-1 -> 0 | G43: =+E43-F43 -> 0 | H43: =IFERROR(G43/F43,0) -> 0
A44: 5245 | C44: =PROPER(+IFERROR(VLOOKUP(A44,'[1]AÑO 2025'!C:I,3,FALSE),0)) -> 0 | E44: =+IFERROR((VLOOKUP((CONCATENATE($K$3,$E$9,$A44)),'[1]AÑO 2026'!$D:$I,6,0)),0)*-1 -> 0 | F44: =+IFERROR((VLOOKUP((CONCATENATE($K$3,$F$9,$A44)),'[1]AÑO 2025'!$D:$I,6,0)),0)*-1 -> 0 | G44: =+E44-F44 -> 0 | H44: =IFERROR(G44/F44,0) -> 0
...

Sheet BALANCE POR TERCEROS 
B1: Libro Mayor
B2: OFTALMOLOGOS EL TESORO SAS 900755062-1
B3: Libro: LIBRO-BASE - Moneda: COP - Cuentas: Mayores e Imputables
B4: Periodos: Julio 2026 - Julio 2026
A6: Cuenta | B6: Nombre Cuenta | C6: Saldo Anterior | D6: Débito | E6: Crédito | F6: Neto | G6: Saldo Final
A7: 1 | B7: Activos | C7: 1.3698791e+10 | D7: 4.8735697e+09 | E7: 4.9152934e+09 | F7: -41723779 | G7: 1.3657067e+10
A8: 11 | B8: Efectivo y Equivalentes del Efectivo | C8: -1.7276078e+08 | D8: 1.8535466e+09 | E8: 1.6850003e+09 | F8: 1.6854623e+08 | G8: -4214553.1
A9: 1105 | B9: Caja | C9: 35922644 | D9: 309142862 | E9: 3.0601158e+08 | F9: 3131281.6 | G9: 39053925
A10: 110505 | B10: Caja General | C10: 60554 | D10: 2500000 | E10: 2161714 | F10: 338286 | G10: 398840
A11: 11050501 | B11: Caja menor OET | C11: 60554 | D11: 2500000 | E11: 2161714 | F11: 338286 | G11: 398840
A12: 110510 | B12: Cajas Menores | C12: 35862090 | D12: 306642862 | E12: 3.0384987e+08 | F12: 2792995.6 | G12: 38655085
A13: 11051001 | B13: Caja General | C13: 38897752 | D13: 245167650 | E13: 2.4237465e+08 | F13: 2792995.6 | G13: 41690748
A14: 11051003 | B14: Caja ajustes año 2021 | C14: 3537.8 | D14: 0 | E14: 0 | F14: 0 | G14: 3537.8
A15: 11051004 | B15: Caja cruce de cuentas | C15: -3039200 | D15: 61475212 | E15: 61475212 | F15: 0 | G15: -3039200
A16: 901216768 | B16: ADELANTE SOLUCIONES FINANCIERAS S.A.S. | C16: -386750 | D16: 0 | E16: 0 | F16: 0 | G16: -386750
A17: 22034122 | B17: ALIDIA DEL SOCORRO CANO AGUIRRE | C17: 5200000 | D17: 0 | E17: 0 | F17: 0 | G17: 5200000
A18: 1020458695 | B18: ALLISON ZAHIRA ARIAS LOPEZ | C18: 116025 | D18: 0 | E18: 0 | F18: 0 | G18: 116025
A19: 8392348 | B19: ANGEL DE JESUS GIL AVENDAÑO | C19: -700400 | D19: 0 | E19: 0 | F19: 0 | G19: -700400
A20: PA0898216 | B20: ANGEL JAVIER PAZ ARROCHA | C20: 150000 | D20: 0 | E20: 0 | F20: 0 | G20: 150000
A21: 1037637940 | B21: ANGIE SALOME ECHEVERRI CARMONA | C21: 78540 | D21: 0 | E21: 0 | F21: 0 | G21: 78540
A22: NY3942BC6 | B22: AZALIAH HAILEY CROES | C22: -409000 | D22: 0 | E22: 0 | F22: 0 | G22: -409000
A23: NY39442BC6 | B23: AZALIAH HAILEY CROES | C23: 409000 | D23: 0 | E23: 0 | F23: 0 | G23: 409000
A24: 901630573 | B24: BLACK MAMMOTH SURGICAL SAS | C24: -1964800 | D24: 0 | E24: 9197082 | F24: -9197082 | G24: -11161882
A25: 70554597 | B25: CARLOS ALBERTO RESTREPO AREIZA | C25: -6378000 | D25: 0 | E25: 0 | F25: 0 | G25: -6378000
A26: 2000012254 | B26: CAROLINA SARDI | C26: 801000 | D26: 0 | E26: 0 | F26: 0 | G26: 801000
A27: 44003672 | B27: CLAUDIA HENAO GARCIA | C27: -101000 | D27: 0 | E27: 0 | F27: 0 | G27: -101000
A28: 32444912 | B28: CONSUELO RESTREPO | C28: 53500 | D28: 0 | E28: 0 | F28: 0 | G28: 53500
A29: 1000088363 | B29: DARWIN ALEXANDER BUSTAMANTE MONTOYA | C29: 154700 | D29: 0 | E29: 0 | F29: 0 | G29: 154700
A30: 32227466 | B30: DIANA CRISTINA MIRA PATIÑO | C30: 1940000 | D30: 0 | E30: 0 | F30: 0 | G30: 1940000
A31: 42866008 | B31: DORALBA NARANJO HENAO | C31: 3489000 | D31: 0 | E31: 0 | F31: 0 | G31: 3489000
A32: 1037617376 | B32: ELIANA LONDOÑO CANO | C32: -1068400 | D32: 0 | E32: 0 | F32: 0 | G32: -1068400
A33: 1035870331 | B33: ELIANA MARCELA URQUIJO RAMIREZ | C33: 83300 | D33: 0 | E33: 0 | F33: 0 | G33: 83300
A34: 16585666 | B34: ELMER TORRES TORRES CASTRO | C34: -8064000 | D34: 0 | E34: 0 | F34: 0 | G34: -8064000
A35: 901503425 | B35: ESTRADA VANEGAS S.A.S. | C35: 101000 | D35: 0 | E35: 0 | F35: 0 | G35: 101000
... A62: 530962818 | B62: RICHARD DUENAS | C62: 420000 | D62: 0 | E62: 0 | F62: 0 | G62: 420000
A63: A80131390 | B63: RICHARD WILLIAM DUENAS | C63: -420000 | D63: 0 | E63: 0 | F63: 0 | G63: -420000
A64: 1000633916 | B64: SIMON FRANCO URIBE URIBE | C64: 165000 | D64: 0 | E64: 0 | F64: 0 | G64: 165000
A65: 1090388155 | B65: TATIANA HERNANDEZ SALAZAR | C65: 705800 | D65: 0 | E65: 0 | F65: 0 | G65: 705800
A66: 1120 | B66: Cuentas de Ahorro | C66: -2.0868342e+08 | D66: 1.5444037e+09 | E66: 1.3789888e+09 | F66: 1.6541494e+08 | G66: -43268479
A67: 112005 | B67: Bancos | C67: -2.0868342e+08 | D67: 1.5444037e+09 | E67: 1.3789888e+09 | F67: 1.6541494e+08 | G67: -43268479
...
